Workbook
Name TipoAmostra: #REF!
Name TipoAmostra: #REF!
Name TipoAmostra: #REF!

Sheet DadosGerais
I2: SERVIÇO GEOLÓGICO DO BRASIL-SGB
I3: Av. Pasteur, nº 404
I4: Cep: 22.290-255 - URCA - RIO DE JANEIRO - RJ
I5: CNPJ: 00.091.652/0002-60
I6: Fone:+55 (21) 2295-0032
B7: ORDEM DE SERVIÇO PARA EXECUÇÃO CONTRATUAL, CONTRATO Nº 081/2023, PREGÃO ELETRÔNICO Nº 11/2023 - UASG 495130, PROCESSO 001216/2022-35 - PREPARAÇÃO E ANÁLISES QUÍMICAS V05/2024
B8: INFORMAÇÃO DA EMPRESA CONTRATADA
B9: SGS GEOSOL LABORATÓRIOS LTDA.
B10: Rod. MG 10 – Km 24,5 – Bairro Angicos
B11: Cep: 33.200-000 - Vespasiano - MG
B12: CNPJ: 02.417.115/0001-01 – Insc. E. 062.113648.00-55
B13: Fone:+55 (31) 3045-0201 - Fax: +55 (31) 3045-0223 E-MAIL: sgsgeosol@sgsgeosol.com.br
B14: INFORMAÇÃO DO SOLICITANTE
B15: * Nome do requerente das análises: | F15: VIVIANE CARILLO FERRARI
D16: * Unidade Regional: | F16: SGB-CPRM - SERVIÇO GEOLÓGICO DO BRASIL - SUREG SÃO PAULO
E17: Endereço: | F17: =VLOOKUP($F$16,Controle!R3:W16,3,FALSE) -> Rua Costa, 55 Bairro Cerqueira César
E18: CEP: | F18: =VLOOKUP($F$16,Controle!R3:W16,4,FALSE) -> 01304-010 | H18: Cidade – UF: | J18: =VLOOKUP($F$16,Controle!R3:W16,6,FALSE) -> SÃO PAULO / SP
E19: Fone / Fax: | F19: =VLOOKUP($F$16,Controle!R3:W16,5,FALSE) -> 11-3775 5101 | H19: E-mail: | J19: =VLOOKUP($F$15,Controle!R20:U54,2,FALSE) -> viviane.ferrari@sgb.gov.br
B20: ENDEREÇO E DADOS PARA O ENVIO DA FATURA
D21: Nome responsável: | F21: DALIANE BANDEIRA EBERHARDT
E22: Empresa: | F22: SGB - CPRM - SERVIÇO GEOLÓGICO DO BRASIL
E23: Endereço: | F23: SETOR MARISTA | I23: Cidade – UF: | K23: GOIANIA/GO
E24: CEP: | F24: 74170-110 | I24: Fone / Fax: | K24: (81)3316-1420/(21)2546-0475
E25: CPF / CNPJ: | F25: 00.091.652/0006-53 | I25: E-mail: | K25: digeoqlab@sgb.gov.br
B26: * E-MAIL´S PARA RECEBIMENTO DOS RESULTADOS
B27: 01. | C27: DIGEOQ | E27: digeoqlab@sgb.gov.br | H27: 05. | I27: equipe.consistencia@sgb.gov.br
B28: 02. | C28: GEREMI/CHEFE DE DIVISÃO | H28: 06.
B29: 03. | C29: GEOQUÍMICO | H29: 07.
B30: 04. | C30: CHEFE DE PROJETO | E30: lucy.chemale@sgb.gov.br | H30: 08.
B31: INSTRUÇÕES ESPECIAIS:
B32: Os resultados no formato digital (excel e pdf) deverão ser enviados para todos os e-mail´s informados acima. No boletim analítico deverá conter: número do lote, centro de custo, nome do requerente e sureg. Em análises envolvendo sedimentos de corrente todo o material processado deve ser devolvido. O e-mail comunicando a devolução das alíquotas e reservas de polpas deverá ser enviado para os e-mails: redelitotecas@cprm.gov.br e digeoqlab@sgb.gov.br Informar o endereço da Litoteca que as amostras deverão ser devolvidas.
C39: RESERVADO P/ USO DO LABORATÓRIO | I39: RESUMO DA SOLICITAÇÃO
C40: Chegada: / / | I40: Total de amostras: | K40: =DadosAmostras!L110 -> 50
C41: Am. Arquivo | F41: Preparada | I41: * Projeto : | K41: =IFERROR(VLOOKUP(K42,Controle!E2:F131,2,FALSE),"") -> Geologia e Potencial Mineral do Sudeste do Paraná
C42: Conf.Orçamento | F42: Peso: | I42: * Centro de Custo: | K42: 4607.084
C43: Filial: | I43: * Nº Requisição R.A.:
C44: Liber.PCP: | I44: * Nº Contrato: | K44: 081/2023
C45: N° do Certif. | I45: * Nº da Nota de Empenho
C46: Entrada: | I46: * Data :
C47: Coord.EXP. | I47: * Assinatura do DIGEOQ:
...

Sheet DadosAmostras
C7: ORDEM DE SERVIÇO PARA EXECUÇÃO CONTRATUAL - CONTRATO SGB/CPRM X SGS GEOSOL
C8: COORDENADAS DA AMOSTRA SOMENTE EM GEOGRÁFICA DECIMAL | E8: Número de Campo | F8: Para amostra de rocha indicar o litotipo (nome de campo) | G8: Número de Lote | H8: Número Laboratório | I8: Tipo de amostra | J8: Matriz | K8: Peso da amostra (g) | L8: PREPARAÇÃO | W8: MÉTODOS DE ANÁLISE | BY8: Material de referência utilizado pelo laboratório p/ XRF | BZ8: Massa mínima de amostra já preparada necessária para garantir a execução do processo analítico e possíveis reanálises | CA8: OBSERVAÇÕES
L9: 1 | M9: 2 | N9: 3 | O9: 4 | P9: 5 | Q9: 6 | R9: 7 | S9: 8 | T9: 9 | U9: 10 | V9: 11 | W9: 12 | X9: 13 | Y9: 14 | Z9: 15 | AA9: 16 | AB9: 17 | AC9: 18 | AD9: 19 | AE9: 20 | AF9: 21 | AG9: 22 | AH9: 23 | AI9: 24 | AJ9: 25 | AK9: 26 | AL9: 27 | AM9: 28 | AN9: 29 | AO9: 30 | AP9: 31 | AQ9: 32 | AR9: 33 | AS9: 34 | AT9: 35 | AU9: 36 | AV9: 37 | AW9: 38 | AX9: 39 | AY9: 40 | AZ9: 41 | BA9: 42 | BB9: 43 | BC9: 44 | BD9: 45 | BE9: 46 | BF9: 47 | BG9: 48 | BH9: 49 | BI9: 50 | BJ9: 51 | BK9: 52 | BL9: 53 | BM9: 54 | BN9: 55 | BO9: 56 | BP9: 57 | BQ9: 58 | BR9: 59 | BS9: 60 | BT9: 61 | BU9: 62 | BV9: 63 | BW9: 64 | BX9: 65
L10: 35.45 | M10: 12.04 | N10: 31.45 | O10: 7.13 | P10: 29.84 | Q10: 8.78 | R10: 4.92 | S10: 2.13 | T10: 11.88 | U10: 23.59 | V10: 3.49 | W10: 36.21 | X10: 28.38 | Y10: 335.33 | Z10: 335.33 | AA10: 210.67 | AB10: 341.46 | AC10: 341.46 | AD10: 357.13 | AE10: 378.23 | AF10: 336.23 | AG10: 282.12 | AH10: 113.31 | AI10: 58.26 | AJ10: 106.18 | AK10: 114.95 | AL10: 109.73 | AM10: 130.63 | AN10: 151.53 | AO10: 114.95 | AP10: 120.18 | AQ10: 148.91 | AR10: 99.28 | AS10: 125.4 | AT10: 99.56 | AU10: 67.94 | AV10: 50.88 | AW10: 90.25 | AX10: 71.54 | AY10: 58.26 | AZ10: 50.48 | BA10: 80.31 | BB10: 73.59 | BC10: 91.99 | BD10: 90.21 | BE10: 180.45 | BF10: 50.48 | BG10: 80.31 | BH10: 53.51 | BI10: 53.51 | BJ10: 53.51 | BK10: 59.46 | BL10: 69.36 | BM10: 33.44 | BN10: 19 | BO10: 101.24 | BP10: 102.21 | BQ10: 81.76 | BR10: 88.07 | BS10: 96.86 | BT10: 50.59 | BU10: 88.8 | BV10: 157.87 | BW10: 55.03 | BX10: 66.34
C11: LONG | D11: LAT | L11: PRP102_E-A (R$/amostra) | M11: PRP102_E-B (R$/kg) | N11: PRP102_Y-A (R$/amostra) | O11: PRP102_Y-B (R$/kg) | P11: PREPS80P-A (R$/amostra) | Q11: PREPS80P-B (R$/kg) | R11: DUP_Brita | S11: DUP_Polpa | T11: PRP250 | U11: PRPGA | V11: LOG03 | W11: PHY04V | X11: DRY10 | Y11: CCR | Z11: CCR_NL | AA11: CCR_GR | AB11: CCR_Mn | AC11: CCR_Fe | AD11: CCR_PO | AE11: CCR_PTR | AF11: CCR_LS | AG11: CCR_PL | AH11: CCSS I | AI11: CCSS II | AJ11: XRF79C_13 | AK11: XRF72FE | AL11: XRF72LS | AM11: XRF72PO | AN11: XRF72PTR | AO11: XRF82MN | AP11: XRF82GR | AQ11: XRF76R | AR11: XRF80B | AS11: XRF82CR | AT11: IMS95A | AU11: ICP95A/IMS95A | AV11: ICP95A | AW11: IMS95RS | AX11: ICM40B | AY11: ICM14B_10 | AZ11: CSA17V_C | BA11: GC_CSA17V_C | BB11: CSA03V | BC11: CSA02V | BD11: CSA05V | BE11: CSA20V | BF11: CSA17V_S | BG11: GC_CSA17V_S | BH11: CLA80C | BI11: CLA70C | BJ11: ISE03A | BK11: XRF75V | BL11: ICM90A_B | BM11: ICP40B | BN11: ICP40B_S | BO11: ICP90A_S | BP11: XRF83B | BQ11: XRF72NL | BR11: XRF72BX | BS11: ICP05V | BT11: ICP90A | BU11: ICM90A | BV11: ICM42Q | BW11: FAA313 / FAA323 | BX11: FAI515
L12: 0 | P12: 0 | Y12: 20 | Z12: 20 | AA12: 20 | AB12: 20 | AC12: 20 | AD12: 20 | AE12: 20 | AF12: 20 | AG12: 20 | AH12: 150 | AI12: 10 | AJ12: 10 | AK12: 10 | AL12: 10 | AM12: 10 | AN12: 10 | AO12: 10 | AP12: 10 | AQ12: 10 | AR12: 10 | AS12: 10 | AT12: 10 | AU12: 10 | AV12: 10 | AW12: 10 | AX12: 10 | AY12: 10 | AZ12: 10 | BA12: 10 | BB12: 10 | BC12: 10 | BD12: 10 | BE12: 10 | BF12: 10 | BG12: 10 | BH12: 10 | BI12: 10 | BJ12: 10 | BK12: 10 | BL12: 10 | BM12: 10 | BN12: 10 | BO12: 10 | BP12: 10 | BQ12: 10 | BR12: 10 | BS12: 10 | BT12: 10 | BU12: 10 | BV12: 20 | BW12: 150 | BX12: 300
B13: 1 | C13: -48.000082 | D13: -24.960217 | E13: 4077-RB-S-015 | G13: 1532/SP | H13: IBV895 | I13: Sed.Corrente | J13: Não se aplica | K13: 1000 | M13: =IF(COUNTA(L13)=1,$K13/1000*M$10,"") | O13: =IF(COUNTA(N13)=1,$K13/1000*O$10,"") | P13: x | Q13: =IF(COUNTA(P13)=1,$K13/1000*Q$10,"") -> 8.78 | AH13: x | BZ13: =SUMIF($L13:$BX13, "x", $L$12:$BX$12) -> 150
B14: 2 | C14: -48.144252 | D14: -24.908233 | E14: 4077-RB-S-047 | G14: 1532/SP | H14: IBV896 | I14: Sed.Corrente | J14: Não se aplica | K14: 1000 | M14: =IF(COUNTA(L14)=1,$K14/1000*M$10,"") | O14: =IF(COUNTA(N14)=1,$K14/1000*O$10,"") | P14: x | Q14: =IF(COUNTA(P14)=1,$K14/1000*Q$10,"") -> 8.78 | AH14: x | BZ14: =SUMIF($L14:$BX14, "x", $L$12:$BX$12) -> 150
B15: 3 | C15: -48.125781 | D15: -24.911993 | E15: 4077-RB-S-052 | G15: 1532/SP | H15: IBV897 | I15: Sed.Corrente | J15: Não se aplica | K15: 1000 | M15: =IF(COUNTA(L15)=1,$K15/1000*M$10,"") | O15: =IF(COUNTA(N15)=1,$K15/1000*O$10,"") | P15: x | Q15: =IF(COUNTA(P15)=1,$K15/1000*Q$10,"") -> 8.78 | AH15: x | BZ15: =SUMIF($L15:$BX15, "x", $L$12:$BX$12) -> 150
B16: 4 | C16: -48.142887 | D16: -24.90476 | E16: 4077-RB-S-054 | G16: 1532/SP | H16: IBV898 | I16: Sed.Corrente | J16: Não se aplica | K16: 1000 | M16: =IF(COUNTA(L16)=1,$K16/1000*M$10,"") | O16: =IF(COUNTA(N16)=1,$K16/1000*O$10,"") | P16: x | Q16: =IF(COUNTA(P16)=1,$K16/1000*Q$10,"") -> 8.78 | AH16: x | BZ16: =SUMIF($L16:$BX16, "x", $L$12:$BX$12) -> 150
B17: 5 | C17: -48.148019 | D17: -24.899291 | E17: 4077-RB-S-055 | G17: 1532/SP | H17: IBV899 | I17: Sed.Corrente | J17: Não se aplica | K17: 1000 | M17: =IF(COUNTA(L17)=1,$K17/1000*M$10,"") | O17: =IF(COUNTA(N17)=1,$K17/1000*O$10,"") | P17: x | Q17: =IF(COUNTA(P17)=1,$K17/1000*Q$10,"") -> 8.78 | AH17: x | BZ17: =SUMIF($L17:$BX17, "x", $L$12:$BX$12) -> 150
B18: 6 | C18: -48.145697 | D18: -24.898732 | E18: 4077-RB-S-058 | G18: 1532/SP | H18: IBV900 | I18: Sed.Corrente | J18: Não se aplica | K18: 1000 | M18: =IF(COUNTA(L18)=1,$K18/1000*M$10,"") | O18: =IF(COUNTA(N18)=1,$K18/1000*O$10,"") | P18: x | Q18: =IF(COUNTA(P18)=1,$K18/1000*Q$10,"") -> 8.78 | AH18: x | BZ18: =SUMIF($L18:$BX18, "x", $L$12:$BX$12) -> 150
B19: 7 | C19: -48.145697 | D19: -24.898732 | E19: 4077-RB-S-058A | G19: 1532/SP | H19: IBV901 | I19: Sed.Corrente | J19: Não se aplica | K19: 1000 | M19: =IF(COUNTA(L19)=1,$K19/1000*M$10,"") | O19: =IF(COUNTA(N19)=1,$K19/1000*O$10,"") | P19: x | Q19: =IF(COUNTA(P19)=1,$K19/1000*Q$10,"") -> 8.78 | AH19: x | BZ19: =SUMIF($L19:$BX19, "x", $L$12:$BX$12) -> 150
B20: 8 | C20: -47.99475 | D20: -24.887711 | E20: 4077-RB-S-065 | G20: 1532/SP | H20: IBV902 | I20: Sed.Corrente | J20: Não se aplica | K20: 1000 | M20: =IF(COUNTA(L20)=1,$K20/1000*M$10,"") | O20: =IF(COUNTA(N20)=1,$K20/1000*O$10,"") | P20: x | Q20: =IF(COUNTA(P20)=1,$K20/1000*Q$10,"") -> 8.78 | AH20: x | BZ20: =SUMIF($L20:$BX20, "x", $L$12:$BX$12) -> 150
B21: 9 | C21: -48.113422 | D21: -24.874152 | E21: 4077-RB-S-069 | G21: 1532/SP | H21: IBV903 | I21: Sed.Corrente | J21: Não se aplica | K21: 1000 | M21: =IF(COUNTA(L21)=1,$K21/1000*M$10,"") | O21: =IF(COUNTA(N21)=1,$K21/1000*O$10,"") | P21: x | Q21: =IF(COUNTA(P21)=1,$K21/1000*Q$10,"") -> 8.78 | AH21: x | BZ21: =SUMIF($L21:$BX21, "x", $L$12:$BX$12) -> 150
B22: 10 | C22: -48.113583 | D22: -24.873623 | E22: 4077-RB-S-070 | G22: 1532/SP | H22: IBV904 | I22: Sed.Corrente | J22: Não se aplica | K22: 1000 | M22: =IF(COUNTA(L22)=1,$K22/1000*M$10,"") | O22: =IF(COUNTA(N22)=1,$K22/1000*O$10,"") | P22: x | Q22: =IF(COUNTA(P22)=1,$K22/1000*Q$10,"") -> 8.78 | AH22: x | BZ22: =SUMIF($L22:$BX22, "x", $L$12:$BX$12) -> 150
B23: 11 | C23: -48.092217 | D23: -24.867298 | E23: 4077-RB-S-074 | G23: 1532/SP | H23: IBV905 | I23: Sed.Corrente | J23: Não se aplica | K23: 1000 | M23: =IF(COUNTA(L23)=1,$K23/1000*M$10,"") | O23: =IF(COUNTA(N23)=1,$K23/1000*O$10,"") | P23: x | Q23: =IF(COUNTA(P23)=1,$K23/1000*Q$10,"") -> 8.78 | AH23: x | BZ23: =SUMIF($L23:$BX23, "x", $L$12:$BX$12) -> 150
B24: 12 | C24: -48.095948 | D24: -24.864672 | E24: 4077-RB-S-075 | G24: 1532/SP | H24: IBV906 | I24: Sed.Corrente | J24: Não se aplica | K24: 1000 | M24: =IF(COUNTA(L24)=1,$K24/1000*M$10,"") | O24: =IF(COUNTA(N24)=1,$K24/1000*O$10,"") | P24: x | Q24: =IF(COUNTA(P24)=1,$K24/1000*Q$10,"") -> 8.78 | AH24: x | BZ24: =SUMIF($L24:$BX24, "x", $L$12:$BX$12) -> 150
... B68: 50 | C68: -48.465101 | D68: -24.514145 | E68: 4077-RB-S-245 | G68: 1532/SP | H68: IBV944 | I68: Sed.Corrente | J68: Não se aplica | K68: 1000 | M68: =IF(COUNTA(L68)=1,$K68/1000*M$10,"") | O68: =IF(COUNTA(N68)=1,$K68/1000*O$10,"") | P68: x | Q68: =IF(COUNTA(P68)=1,$K68/1000*Q$10,"") -> 8.78 | AH68: x | BZ68: =SUMIF($L68:$BX68, "x", $L$12:$BX$12) -> 150
B69: 51 | M69: =IF(COUNTA(L69)=1,$K69/1000*M$10,"") | O69: =IF(COUNTA(N69)=1,$K69/1000*O$10,"") | Q69: =IF(COUNTA(P69)=1,$K69/1000*Q$10,"") | BZ69: =SUMIF($L69:$BX69, "x", $L$12:$BX$12) -> 0
B70: 52 | M70: =IF(COUNTA(L70)=1,$K70/1000*M$10,"") | O70: =IF(COUNTA(N70)=1,$K70/1000*O$10,"") | Q70: =IF(COUNTA(P70)=1,$K70/1000*Q$10,"") | BZ70: =SUMIF($L70:$BX70, "x", $L$12:$BX$12) -> 0
B71: 53 | M71: =IF(COUNTA(L71)=1,$K71/1000*M$10,"") | O71: =IF(COUNTA(N71)=1,$K71/1000*O$10,"") | Q71: =IF(COUNTA(P71)=1,$K71/1000*Q$10,"") | BZ71: =SUMIF($L71:$BX71, "x", $L$12:$BX$12) -> 0
B72: 54 | M72: =IF(COUNTA(L72)=1,$K72/1000*M$10,"") | O72: =IF(COUNTA(N72)=1,$K72/1000*O$10,"") | Q72: =IF(COUNTA(P72)=1,$K72/1000*Q$10,"") | BZ72: =SUMIF($L72:$BX72, "x", $L$12:$BX$12) -> 0
B73: 55 | M73: =IF(COUNTA(L73)=1,$K73/1000*M$10,"") | O73: =IF(COUNTA(N73)=1,$K73/1000*O$10,"") | Q73: =IF(COUNTA(P73)=1,$K73/1000*Q$10,"") | BZ73: =SUMIF($L73:$BX73, "x", $L$12:$BX$12) -> 0
B74: 56 | M74: =IF(COUNTA(L74)=1,$K74/1000*M$10,"") | O74: =IF(COUNTA(N74)=1,$K74/1000*O$10,"") | Q74: =IF(COUNTA(P74)=1,$K74/1000*Q$10,"") | BZ74: =SUMIF($L74:$BX74, "x", $L$12:$BX$12) -> 0
B75: 57 | M75: =IF(COUNTA(L75)=1,$K75/1000*M$10,"") | O75: =IF(COUNTA(N75)=1,$K75/1000*O$10,"") | Q75: =IF(COUNTA(P75)=1,$K75/1000*Q$10,"") | BZ75: =SUMIF($L75:$BX75, "x", $L$12:$BX$12) -> 0
B76: 58 | M76: =IF(COUNTA(L76)=1,$K76/1000*M$10,"") | O76: =IF(COUNTA(N76)=1,$K76/1000*O$10,"") | Q76: =IF(COUNTA(P76)=1,$K76/1000*Q$10,"") | BZ76: =SUMIF($L76:$BX76, "x", $L$12:$BX$12) -> 0
B77: 59 | M77: =IF(COUNTA(L77)=1,$K77/1000*M$10,"") | O77: =IF(COUNTA(N77)=1,$K77/1000*O$10,"") | Q77: =IF(COUNTA(P77)=1,$K77/1000*Q$10,"") | BZ77: =SUMIF($L77:$BX77, "x", $L$12:$BX$12) -> 0
B78: 60 | M78: =IF(COUNTA(L78)=1,$K78/1000*M$10,"") | O78: =IF(COUNTA(N78)=1,$K78/1000*O$10,"") | Q78: =IF(COUNTA(P78)=1,$K78/1000*Q$10,"") | BZ78: =SUMIF($L78:$BX78, "x", $L$12:$BX$12) -> 0
B79: 61 | M79: =IF(COUNTA(L79)=1,$K79/1000*M$10,"") | O79: =IF(COUNTA(N79)=1,$K79/1000*O$10,"") | Q79: =IF(COUNTA(P79)=1,$K79/1000*Q$10,"") | BZ79: =SUMIF($L79:$BX79, "x", $L$12:$BX$12) -> 0
B80: 62 | M80: =IF(COUNTA(L80)=1,$K80/1000*M$10,"") | O80: =IF(COUNTA(N80)=1,$K80/1000*O$10,"") | Q80: =IF(COUNTA(P80)=1,$K80/1000*Q$10,"") | BZ80: =SUMIF($L80:$BX80, "x", $L$12:$BX$12) -> 0
... B106: 88 | M106: =IF(COUNTA(L106)=1,$K106/1000*M$10,"") | O106: =IF(COUNTA(N106)=1,$K106/1000*O$10,"") | Q106: =IF(COUNTA(P106)=1,$K106/1000*Q$10,"") | BZ106: =SUMIF($L106:$BX106, "x", $L$12:$BX$12) -> 0
B107: Número de amostras por método | L107: =COUNTA(L13:L106) -> 0 | M107: =COUNT(M13:M106) -> 0 | N107: =COUNTA(N13:N106) -> 0 | O107: =COUNT(O13:O106) -> 0 | P107: =COUNTA(P13:P106) -> 50 | Q107: =COUNT(Q13:Q106) -> 50 | R107: =COUNTA(R13:R106) -> 0 | S107: =COUNTA(S13:S106) -> 0 | T107: =COUNTA(T13:T106) -> 0 | U107: =COUNTA(U13:U106) -> 0 | V107: =COUNTA(V13:V106) -> 0 | W107: =COUNTA(W13:W106) -> 0 | X107: =COUNTA(X13:X106) -> 0 | Y107: =COUNTA(Y13:Y106) -> 0 | ... BX107: =COUNTA(BX13:BX106) -> 0
B108: R$ por método | L108: =L10*L107 -> 0 | M108: =SUM(M13:M106) -> 0 | N108: =N10*N107 -> 0 | O108: =SUM(O13:O106) -> 0 | P108: =P10*P107 -> 1492 | Q108: =SUM(Q13:Q106) -> 439 | R108: =R10*R107 -> 0 | S108: =S10*S107 -> 0 | T108: =T10*T107 -> 0 | U108: =U10*U107 -> 0 | V108: =V10*V107 -> 0 | W108: =W10*W107 -> 0 | X108: =X10*X107 -> 0 | Y108: =Y10*Y107 -> 0 | ... BX108: =BX10*BX107 -> 0
B109: R$ total do lote | L109: =SUM(L108:BX108) -> 7596.5
B110: Número total de amostras no lote | L110: =COUNTA(H12:H106) -> 50

Sheet Controle
A1: ID | B1: MATRIZ | D1: ID | E1: CENTRO DE CUSTO | F1: NOME DO PROJETO | H1: ID | I1: TIPO DE AMOSTRA | K1: ID | L1: MRC | N1: ID | O1: LITOTIPO | Q1: UNIDADES REGIONAIS
A2: 1 | B2: Carbonatos | D2: 1 | E2: 1603.084 | F2: Joinville | H2: 1 | I2: CB aluvião | K2: 1 | L2: DST-1 | N2: 1 | O2: ALASKITO | Q2: ID | R2: E-MAIL | S2: RESPONSÁVEL | T2: Endereço | U2: CEP | V2: Fone / Fax | W2: Cidade – UF
A3: 2 | B3: Carvão | D3: 4 | E3: 4106.043 | F3: Recuperação Bacia Carbonífera | H3: 2 | I3: CB rocha | K3: 2 | L3: Basalt BR | N3: 2 | O3: ÁLCALIGRANITO | Q3: 1 | R3: SGB-CPRM - SERVIÇO GEOLÓGICO DO BRASIL - ESCRITÓRIO RIO DE JANEIRO | S3: ESCRITÓRIO RIO DE JANEIRO | T3: Avenida Pasteur, 404 Bairro Urca | U3: 22290-255 | V3: 21-3986-0788 | W3: RIO DE JANEIRO / RJ
A4: 3 | B4: Cassiterita | D4: 5 | E4: 4107.043 | F4: Recuperação Bacia Carbonífera | H4: 3 | I4: CB solo | K4: 3 | L4: BCR-1 | N4: 3 | O4: ÁLCALISIENITO | Q4: 2 | R4: SGB-CPRM - SERVIÇO GEOLÓGICO DO BRASIL - LITOTECA CAETÉ | S4: LITOTECA CAETÉ | T4: Avenida João Pinheiro, 140 Centro | U4: 34800-000 | V4: 31-3651 2031 | W4: CAETÉ / MG
A5: 4 | B5: Fosfato | D5: 6 | E5: 4108.043 | F5: Recuperação Bacia Carbonífera | H5: 4 | I5: Rocha | K5: 4 | L5: BHVO-1 | N5: 4 | O5: ANDESITO | Q5: 3 | R5: SGB-CPRM - SERVIÇO GEOLÓGICO DO BRASIL - RESIDÊNCIA FORTALEZA | S5: RESIDÊNCIA FORTALEZA | T5: Rua Rodrigues Junior, 840 Centro | U5: 60060-000 | V5: 85-3878-0235 | W5: FORTALEZA / CE
A6: 5 | B6: Material Carbonoso | D6: 7 | E6: 4109.043 | F6: Recuperação Bacia Carbonífera | H6: 5 | I6: Saprolito | K6: 5 | L6: AVG-1 | N6: 5 | O6: ANFIBOLITO | Q6: 4 | R6: SGB-CPRM - SERVIÇO GEOLÓGICO DO BRASIL - RESIDÊNCIA PORTO VELHO | S6: RESIDÊNCIA PORTO VELHO | T6: Avenida Lauro Sodré, 2561 Bairro São Sebastião | U6: 76801-581 | V6: 69-3901 3700 | W6: PORTO VELHO / RO
A7: 6 | B7: Min. Cobre | D7: 8 | E7: 4113.084 | F7: Geol. e Geod. da Front. Brasil-Guiana | H7: 6 | I7: Sed.Corrente | K7: 6 | L7: STM-1 | N7: 6 | O7: ANIDRITA | Q7: 5 | R7: SGB-CPRM - SERVIÇO GEOLÓGICO DO BRASIL - RESIDÊNCIA TERESINA | S7: RESIDÊNCIA TERESINA | T7: Rua Goiás, 312 Sul | U7: 64001-570 | V7: 86-3222 4153 | W7: TERESINA / PI
A8: 7 | B8: Min. Ferro | D8: 9 | E8: 4116.084 | F8: NF Contendas-Macajuba | H8: 7 | I8: Solo | K8: 7 | L8: Granite GS-N | N8: 7 | O8: ANORTOSITO | Q8: 6 | R8: SGB-CPRM - SERVIÇO GEOLÓGICO DO BRASIL - SEDE BRASÍLIA | S8: SEDE BRASÍLIA | T8: Setor Bancário Norte - SBN, Quadra 02, Asa Norte, Bloco H - Edifício Central Brasília | U8: 70040-904 | V8: 61-2108 8400 | W8: BRASÍLIA/DF
A9: 8 | B9: Min. Manganês | D9: 10 | E9: 4118.550 | F9: NF Escudo Sul-Riograndense | H9: 8 | I9: Testemunho rocha | K9: 8 | L9: Granite GH | N9: 8 | O9: ANDRACITO | Q9: 7 | R9: SGB-CPRM - SERVIÇO GEOLÓGICO DO BRASIL - SUREG BELÉM | S9: SUREG BELÉM | T9: Avenida Doutor Freitas, 3645 Bairro do Marco | U9: 66095-110 | V9: 91-3182 1300 | W9: BELÉM / PA
A10: 9 | B10: Min. Ouro | D10: 11 | E10: 4119.087 | F10: Britas NE Pará | H10: 9 | I10: Testemunho saprolito | N10: 9 | O10: APLITO | Q10: 8 | R10: SGB-CPRM - SERVIÇO GEOLÓGICO DO BRASIL - SUREG BELO HORIZONTE | S10: SUREG BELO HORIZONTE | T10: Avenida Brasil, 1731 Bairro Funcionários | U10: 30140-002 | V10: 31-3878 0307 | W10: BELO HORIZONTE / MG
A11: 10 | B11: Min. Titânio | D11: 12 | E11: 4120.084 | F11: Geologia do Cráton Amazônico | H11: 10 | I11: Outros | N11: 10 | O11: ARCÓSEO | Q11: 9 | R11: SGB-CPRM - SERVIÇO GEOLÓGICO DO BRASIL - SUREG GOIÂNIA | S11: SUREG GOIÂNIA | T11: Rua 148, 485 Setor Marista | U11: 74170-110 | V11: 62-3240 1400 | W11: GOIÂNIA / GO
A12: 11 | B12: Min. Zn/Pb | D12: 13 | E12: 4183.087 | F12: Levantamentos Geoquímicos | N12: 11 | O12: ARDÓSIA | Q12: 10 | R12: SGB-CPRM - SERVIÇO GEOLÓGICO DO BRASIL - SUREG MANAUS | S12: SUREG MANAUS | T12: Avenida André Araújo, 2160 Bairro Aleixo | U12: 69060-000 | V12: 92-2126 0301 | W12: MANAUS / AM
A13: 12 | B13: Níquel laterítico | D13: 14 | E13: 4201.084 | F13: Mapa Geológico América do Sul | N13: 12 | O13: ARENITO | Q13: 11 | R13: SGB-CPRM - SERVIÇO GEOLÓGICO DO BRASIL - SUREG PORTO ALEGRE | S13: SUREG PORTO ALEGRE | T13: Rua Banco da Província, 105 Bairro Santa Teresa | U13: 90840-030 | V13: 51-3406 7300 | W13: PORTO ALEGRE / RS
A14: 13 | B14: Silicosa | D14: 15 | E14: 4203.084 | F14: Lineamento Azimute 125 | N14: 13 | O14: ARENITO LÍTICO | Q14: 12 | R14: SGB-CPRM - SERVIÇO GEOLÓGICO DO BRASIL - SUREG RECIFE | S14: SUREG RECIFE | T14: Avenida Sul, 2291 Bairro Afogados | U14: 50770-011 | V14: 81-3316 1400 | W14: RECIFE / PE
A15: 14 | B15: Sulfetada | D15: 16 | E15: 4307.370 | F15: NF Granjeiro - Cococi | N15: 14 | O15: ARENITO LITO-FELDSPÁTICO | Q15: 13 | R15: SGB-CPRM - SERVIÇO GEOLÓGICO DO BRASIL - SUREG SALVADOR | S15: SUREG SALVADOR | T15: Avenida Ulysses Guimarães, 2862 Bairro Sussuarana/Centro Administrativo da Bahia | U15: 41213-000 | V15: 71-3230 0025 | W15: SALVADOR / BA
A16: 15 | B16: Rc. Ácida | D16: 17 | E16: 4308.260 | F16: NF Sudeste de Rondônia | N16: 15 | O16: ARGILITO | Q16: 14 | R16: SGB-CPRM - SERVIÇO GEOLÓGICO DO BRASIL - SUREG SÃO PAULO | S16: SUREG SÃO PAULO | T16: Rua Costa, 55 Bairro Cerqueira César | U16: 01304-010 | V16: 11-3775 5101 | W16: SÃO PAULO / SP
A17: 16 | B17: Rc. Alcalina | D17: 18 | E17: 4309.300 | F17: NF Rio Maria | N17: 16 | O17: AUGENGNAISSE
A18: 17 | B18: Rc. Máfica | D18: 19 | E18: 4311.550 | F18: Sudeste do RS | N18: 17 | O18: BASALTO | Q18: PESQUISADORES DIGEOQ
A19: 18 | B19: Rc. Sedimentar | D19: 20 | E19: 4313.350 | F19: NF Rio Capibaribe | N19: 18 | O19: BASALTO TOLEÍTICO | Q19: ID | R19: RESPONSÁVEL | S19: E-MAIL | T19: Unidae Regional | U19: Lotação | V19: Diretora | W19: Departamento
A20: 19 | B20: Rc. Ultramáfica | D20: 21 | E20: 4314.350 | F20: NF Alto Moxotó, PE | N20: 19 | O20: BAUXITO | Q20: 1 | R20: SILVANA DE CARVALHO MELO | S20: silvana.melo@sgb.gov.br | T20: SGB-CPRM - SERVIÇO GEOLÓGICO DO BRASIL - SUREG RECIFE | U20: DIGEOQ | V20: Diretoria de Geologia e Recursos Mierais | W20: Departamento de Geologia Básica
A21: 20 | B21: Terras raras | D21: 22 | E21: 4316.400 | F21: NF Chorrochó - Macururé | N21: 20 | O21: BRECHA DE FALHA | Q21: 2 | R21: BRUNO DE OLIVEIRA CALADO | S21: bruno.calado@sgb.gov.br | T21: SGB-CPRM - SERVIÇO GEOLÓGICO DO BRASIL - RESIDÊNCIA FORTALEZA | U21: DIGEOQ | V21: Diretoria de Geologia e Recursos Mierais | W21: Departamento de Geologia Básica
A22: 21 | B22: Não se aplica | D22: 23 | E22: 4318.650 | F22: NF Oeste de Goiás | N22: 21 | O22: BRECHA VULCÂNICA | Q22: 3 | R22: CAROLINE COUTO SANTOS | S22: caroline.santos@sgb.gov.br | T22: SGB-CPRM - SERVIÇO GEOLÓGICO DO BRASIL - SUREG SALVADOR | U22: DIGEOQ | V22: Diretoria de Geologia e Recursos Mierais | W22: Departamento de Geologia Básica
A23: 22 | B23: Outros | D23: 24 | E23: 4320.087 | F23: ARIM QF Central | N23: 22 | O23: CALCARENITO | Q23: 4 | R23: CESAR LISBOA CHAVES | S23: cesar.chaves@sgb.gov.br | T23: SGB-CPRM - SERVIÇO GEOLÓGICO DO BRASIL - SUREG BELÉM | U23: DIGEOQ | V23: Diretoria de Geologia e Recursos Mierais | W23: Departamento de Geologia Básica
D24: 25 | E24: 4321.087 | F24: ARIM Seridó | N24: 23 | O24: CALCÁRIO | Q24: 5 | R24: DALIANE BANDEIRA EBERHARDT | S24: daliane.eberhardt@sgb.gov.br | T24: SGB-CPRM - SERVIÇO GEOLÓGICO DO BRASIL - SUREG GOIÂNIA | U24: DIGEOQ | V24: Diretoria de Geologia e Recursos Mierais | W24: Departamento de Geologia Básica
D25: 26 | E25: 4322.087 | F25: ARIM Alta Floresta | N25: 24 | O25: CALCÁRIO DOLMÍTICO | Q25: 6 | R25: DOUGLAS ALMEIDA SILVEIRA | S25: douglas.silveira@sgb.gov.br | T25: SGB-CPRM - SERVIÇO GEOLÓGICO DO BRASIL - SUREG BELO HORIZONTE | U25: DIGEOQ | V25: Diretoria de Geologia e Recursos Mierais | W25: Departamento de Geologia Básica
D26: 27 | E26: 4323.260 | F26: ARIM Nova Brasilândia | N26: 25 | O26: CALCÁRIO FERRUGINOSO | Q26: 7 | R26: EDUARDO DUARTE MARQUES | S26: eduardo.marques@sgb.gov.br | T26: SGB-CPRM - SERVIÇO GEOLÓGICO DO BRASIL - SUREG BELO HORIZONTE | U26: DIGEOQ | V26: Diretoria de Geologia e Recursos Mierais | W26: Departamento de Geologia Básica
D27: 28 | E27: 4326.087 | F27: ARIM QF SVS | N27: 26 | O27: CARBONATITO | Q27: 8 | R27: FELIPE ROCHA ABREU | S27: felipe.abreu@sgb.gov.br | T27: SGB-CPRM - SERVIÇO GEOLÓGICO DO BRASIL - RESIDÊNCIA FORTALEZA | U27: DIGEOQ | V27: Diretoria de Geologia e Recursos Mierais | W27: Departamento de Geologia Básica
D28: 29 | E28: 4328.087 | F28: ARIM Borda NW CSF | N28: 27 | O28: CARVÃO | Q28: 9 | R28: JOÃO HENRIQUE LARIZZATTI | S28: joao.larizzati@sgb.gov.br | T28: SGB-CPRM - SERVIÇO GEOLÓGICO DO BRASIL -ESCRITÓRIO DO RIO DE JANEIRO | U28: DIGEOQ | V28: Diretoria de Geologia e Recursos Mierais | W28: Departamento de Geologia Básica
D29: 30 | E29: 4329.087 | F29: ARIM Serra de Jacobina | N29: 28 | O29: CASCALHO | Q29: 10 | R29: ANDREIA GROSS | S29: andreia.gross@sgb.gov.br | T29: SGB-CPRM - SERVIÇO GEOLÓGICO DO BRASIL - SUREG PORTO ALEGRE | U29: DIGEOQ | V29: Diretoria de Geologia e Recursos Mierais | W29: Departamento de Geologia Básica
D30: 31 | E30: 4330.087 | F30: ARIM Batólito de Pelotas | N30: 29 | O30: CATACLASITO | Q30: 11 | R30: MARCELY PEREIRA NEVES | S30: marcely.neves@sgb.gov.br | T30: SGB-CPRM - SERVIÇO GEOLÓGICO DO BRASIL - SUREG BELÉM | U30: DIGEOQ | V30: Diretoria de Geologia e Recursos Mierais | W30: Departamento de Geologia Básica
D31: 32 | E31: 4332.087 | F31: ARIM Remanso-Sobradinho | N31: 30 | O31: CAULIM | Q31: 12 | R31: MICHELE ZORZETTI PITARELLO | S31: michele.pitarello@sgb.gov.br | T31: SGB-CPRM - SERVIÇO GEOLÓGICO DO BRASIL - SUREG MANAUS | U31: DIGEOQ | V31: Diretoria de Geologia e Recursos Mierais | W31: Departamento de Geologia Básica
D32: 33 | E32: 4334.087 | F32: ARIM Carajás | N32: 31 | O32: CHARNOCKITO | Q32: 13 | R32: VIVIANE CARILLO FERRARI | S32: viviane.ferrari@sgb.gov.br | T32: SGB-CPRM - SERVIÇO GEOLÓGICO DO BRASIL - SUREG SÃO PAULO | U32: DIGEOQ | V32: Diretoria de Geologia e Recursos Mierais | W32: Departamento de Geologia Básica
D33: 34 | E33: 4335.087 | F33: ARIM Tapajós | N33: 32 | O33: CHERT | Q33: 1 | R33: WILSON LOPES DE OLIVEIRA NETO | S33: wilson.oliveira@sgb.gov.br | T33: SGB-CPRM - SERVIÇO GEOLÓGICO DO BRASIL - SUREG SALVADOR | U33: DIGEOQ | V33: Diretoria de Geologia e Recursos Mierais | W33: Departamento de Geologia Básica
D34: 35 | E34: 4337.087 | F34: ARIM Central Faixa Brasília | N34: 33 | O34: CONCREÇÕES FERRUGINOSAS | Q34: 2 | R34: PATRICK ARAÚJO DOS SANTOS | S34: patrick.santos@sgb.gov.br | T34: SGB-CPRM - SERVIÇO GEOLÓGICO DO BRASIL - SUREG SALVADOR | U34: DEGEO-DIGEOB | V34: Diretoria de Geologia e Recursos Mierais | W34: Departamento de Geologia Básica
D35: 36 | E35: 4338.087 | F35: ARIM Ametista Ágata - RS | N35: 34 | O35: CONCREÇÕES MANGANÍFERAS | Q35: 3 | R35: JOSENEUSA BRILHANTE RODRIGUES | S35: joseneusa.rodrigues@sgb.gov.br | T35: SGB-CPRM - SERVIÇO GEOLÓGICO DO BRASIL - SEDE BRASÍLIA | U35: DEGEO-DIGEOD | V35: Diretoria de Geologia e Recursos Mierais | W35: Departamento de Geologia Básica
... D42: 43 | E42: 4357.087 | F42: Calcários da Bahia | N42: 41 | O42: DIABÁSIO | Q42: 10 | R42: IONÁ CUNHA | S42: iona.cunha@sgb.gov.br | T42: SGB-CPRM - SERVIÇO GEOLÓGICO DO BRASIL - SUREG SALVADOR | U42: DEREM-DIPEME | V42: Diretoria de Geologia e Recursos Mierais | W42: Departamento de Recursos Mineais
D43: 44 | E43: 4358.087 | F43: ARIM Aripuanã | N43: 42 | O43: DIATOMITO | Q43: 11 | R43: JONATHAN NEREU LISBOA ROJAS | S43: jonathan.rojas@sgb.gov.br | T43: SGB-CPRM - SERVIÇO GEOLÓGICO DO BRASIL - LITOTECA CAETÉ | U43: LITOTECA CAETÉ | V43: Diretoria de Inraestrutura Geocient[ifica
D44: 45 | E44: 4359.087 | F44: ARIM Sudeste do Amazonas | N44: 43 | O44: DIORITO | Q44: 12 | R44: EDNEY SMITH DE MORAES PALHETA | S44: edney.palheta@sgb.gov.br | T44: SGB-CPRM - SERVIÇO GEOLÓGICO DO BRASIL - RESIDÊNCIA FORTALEZA | U44: RESIDÊNCIA FORTALEZA | V44: Diretoria de Geologia e Recursos Mierais | W44: Departamento de Geologia Básica
D45: 46 | E45: 4361.087 | F45: Potencialidade de RO-RN | N45: 44 | O45: DOLOMITO | Q45: 13 | R45: CARLOS EDUARDO S. OLIVEIRA | S45: carlos.oliveira@sgb.gov.br | T45: SGB-CPRM - SERVIÇO GEOLÓGICO DO BRASIL - RESIDÊNCIA PORTO VELHO | U45: RESIDÊNCIA PORTO VELHO | V45: Diretoria de Geologia e Recursos Mierais | W45: Departamento de Geologia Básica
D46: 47 | E46: 4362.260 | F46: ARIM PER | N46: 45 | O46: DUNITO | Q46: 14 | R46: FRANCISCO RUBENS DE SOUSA | S46: francisco.sousa@sgb.gov.br | T46: SGB-CPRM - SERVIÇO GEOLÓGICO DO BRASIL - RESIDÊNCIA TERESINA | U46: RESIDÊNCIA TERESINA | V46: Diretoria de Geologia e Recursos Mierais | W46: Departamento de Geologia Básica
...
